Workbook

Sheet Start Here
A1: Product Master List - all 3 Pinterest accounts
A2: Built Oct 30, 2026 for Dr. Q. One row = one product. Each month = 150 pins per account (5 a day).
A4: Tab
A5: TPT - School Templates: every product publicly listed in the TPT store, the Pinterest board it pins to, and which monthly rotation it runs in.
A6: Amazon - Dr Q Kids: 150 Amazon products for Dr. Q | Screen-Free Kid Toys, with the exact parent search phrase for each pin and the affiliate link.
A7: Amazon - Sideline Ready: 150 Amazon products for Sideline Ready (50 already pinned in November + 100 new).
A8: Summary: live counts by board, season and rotation (formulas - they update if you edit the tabs).
A10: How the Amazon products were picked
A11: Every Amazon product showed '1K+ bought in past month' or more on Amazon search, was not a sponsored listing, and rated 4.2 stars or higher when checked (Oct 2026).
A12: Each product is matched to a phrase parents actually type into Pinterest search - that phrase goes in the pin title, description and alt text.
A13: Season column = when to push it hardest. Year-round products can run every month; winter products Nov-Feb; summer products Mar-Aug.
A14: Amazon sales counts and prices change. Each month before building pins I re-check that every product still has 1K+ sales and swap any that dropped.
... A23: Sideline Ready links use your current tracking ID (screenfreet0f-20). If you make a separate ID for Sideline Ready, send it and I'll swap every link.

Sheet TPT - School Templates
A1: # | B1: Product | C1: Format | D1: Type | E1: Pinterest board | F1: Rotation | G1: TPT ID | H1: TPT link
A2: 1 | B2: Autism Evaluation Report | Educational eligibility | C2: EDITABLE WORD | D2: Bundle / kit / library | E2: School Psychologist Templates & Report Tools | F2: A + B (every month) | G2: 17900932 | H2: https://www.teacherspayteachers.com/Product/Autism-Evaluation-Report-Template-Educational-Eligibility-Editable-Word-17900932
A3: 2 | B3: BASC-3 & BASC-4 Bundle | Conners 4, BRIEF-2, CDI 2 + FBA/BIP | C3: EDITABLE WORD | D3: Bundle / kit / library | E3: School Psychologist Templates & Report Tools | F3: A + B (every month) | G3: 18021102 | H3: https://www.teacherspayteachers.com/Product/BASC-3-BASC-4-Report-Template-Bundle-Conners-4-BRIEF-2-CDI-2-FBA-BIP-18021102
A4: 3 | B4: Bilingual Psychoed Report | English learner evaluation | C4: EDITABLE WORD | D4: Bundle / kit / library | E4: School Psychologist Templates & Report Tools | F4: A + B (every month) | G4: 18044838 | H4: https://www.teacherspayteachers.com/Product/Bilingual-Psychoeducational-Report-Template-English-Learner-Evaluation-Word-18044838
A5: 4 | B5: Cognitive Assessment Bundle | 8 cognitive report templates | C5: EDITABLE WORD | D5: Bundle / kit / library | E5: School Psychologist Templates & Report Tools | F5: A + B (every month) | G5: 17902110 | H5: https://www.teacherspayteachers.com/Product/Cognitive-Assessment-Bundle-8-Cognitive-Report-Templates-Editable-Word-17902110
A6: 5 | B6: DD Eligibility Report | Preschool developmental delay | C6: EDITABLE WORD | D6: Bundle / kit / library | E6: School Psychologist Templates & Report Tools | F6: A + B (every month) | G6: 18040189 | H6: https://www.teacherspayteachers.com/Product/Developmental-Delay-Eligibility-Report-Template-Preschool-DD-Word-18040189
A7: 6 | B7: ED Eligibility Report | Emotional disturbance evaluation | C7: EDITABLE WORD | D7: Bundle / kit / library | E7: School Psychologist Templates & Report Tools | F7: A + B (every month) | G7: 17901426 | H7: https://www.teacherspayteachers.com/Product/Emotional-Disturbance-ED-Eligibility-Report-Template-Editable-Word-17901426
A8: 7 | B8: Gifted Evaluation Report | Multiple-criteria write-up | C8: EDITABLE WORD | D8: Bundle / kit / library | E8: School Psychologist Templates & Report Tools | F8: A + B (every month) | G8: 18040234 | H8: https://www.teacherspayteachers.com/Product/Gifted-Evaluation-Report-Template-Multiple-Criteria-Write-Up-Word-18040234
A9: 8 | B9: ID Eligibility Report | Intellectual disability evaluation | C9: EDITABLE WORD | D9: Bundle / kit / library | E9: School Psychologist Templates & Report Tools | F9: A + B (every month) | G9: 18044773 | H9: https://www.teacherspayteachers.com/Product/ID-Eligibility-Report-Template-Intellectual-Disability-Evaluation-Word-18044773
A10: 9 | B10: IEE Review Template | Independent educational evaluation summary | C10: EDITABLE WORD | D10: Bundle / kit / library | E10: School Psychologist Templates & Report Tools | F10: A + B (every month) | G10: 18044864 | H10: https://www.teacherspayteachers.com/Product/IEE-Review-Template-Independent-Educational-Evaluation-Summary-Word-18044864
A11: 10 | B11: OHI Eligibility Report | Other health impairment + ADHD | C11: EDITABLE WORD | D11: Bundle / kit / library | E11: School Psychologist Templates & Report Tools | F11: A + B (every month) | G11: 18044907 | H11: https://www.teacherspayteachers.com/Product/OHI-Eligibility-Report-Template-Other-Health-Impairment-ADHD-Word-18044907
A12: 11 | B12: Parent Questionnaire | Developmental history for evaluations | C12: EDITABLE WORD | D12: Bundle / kit / library | E12: School Psychologist Templates & Report Tools | F12: A + B (every month) | G12: 17901591 | H12: https://www.teacherspayteachers.com/Product/Parent-Questionnaire-for-Psychoeducational-Evaluations-Developmental-History-17901591
A13: 12 | B13: Psychoeducational Report | School psychologist evaluation shell | C13: EDITABLE WORD | D13: Bundle / kit / library | E13: School Psychologist Templates & Report Tools | F13: A + B (every month) | G13: 17901638 | H13: https://www.teacherspayteachers.com/Product/Psychoeducational-Report-Template-School-Psychologist-Evaluation-Shell-17901638
... A221: 220 | B221: WRMT-III Report Template | Woodcock Reading Mastery Tests | C221: EDITABLE WORD | D221: Test report template | E221: School Psychologist Templates & Report Tools | F221: B | G221: 18030977 | H221: https://www.teacherspayteachers.com/Product/WRMT-III-Report-Template-Woodcock-Reading-Mastery-Tests-Write-Up-Word-18030977

Sheet Amazon - Dr Q Kids
A1: # | B1: Product | C1: Price (Oct 30) | D1: Stars | E1: Ratings | F1: Bought last month | G1: Season | H1: Pin search phrase | I1: Topic | J1: More parent search phrases | K1: Pinterest board | L1: ASIN | M1: Affiliate link
A2: 1 | B2: Geokay 16" Rechargeable LED Light Drawing Board | C2: $29.99 | D2: 4.6 | E2: 2.1K | F2: 10K+ | G2: Nov-Feb (holiday & winter) | H2: screen free christmas gifts | I2: screen free christmas gifts | J2: screen free gifts for kids; screen free toys for kids; christmas gifts for kids not toys | K2: Screen-Free Gifts for Kids by Age | L2: B0F8NMN1YK | M2: https://www.amazon.com/dp/B0F8NMN1YK?tag=screenfreet0f-20
A3: 2 | B3: Skillmatics Guess in 10: Animals Game | C3: $19.97 | D3: 4.8 | E3: 116 | F3: 5K+ | G3: Nov-Feb (holiday & winter) | H3: screen free gifts for kids | I3: screen free christmas gifts | J3: screen free gifts for kids; screen free toys for kids; christmas gifts for kids not toys | K3: Screen-Free Gifts for Kids by Age | L3: B0GLGL8LPS | M3: https://www.amazon.com/dp/B0GLGL8LPS?tag=screenfreet0f-20
A4: 3 | B4: Colorful LCD Writing Tablet for Kids | C4: $9.99 | D4: 4.5 | E4: 6.1K | F4: 2K+ | G4: Nov-Feb (holiday & winter) | H4: screen free toys for kids | I4: screen free christmas gifts | J4: screen free gifts for kids; screen free toys for kids; christmas gifts for kids not toys | K4: Screen-Free Gifts for Kids by Age | L4: B0CGV5K97C | M4: https://www.amazon.com/dp/B0CGV5K97C?tag=screenfreet0f-20
A5: 4 | B5: Meland Doctor Kit with Puppy | C5: $23.20 | D5: 4.6 | E5: 8.7K | F5: 10K+ | G5: Nov-Feb (holiday & winter) | H5: gift ideas for 3 year olds | I5: gift ideas for 3 year olds | J5: gift ideas for 3 year girl; gift ideas for 3 year boy; educational toys for 3 year | K5: Screen-Free Gifts for Kids by Age | L5: B09PD6YWF1 | M5: https://www.amazon.com/dp/B09PD6YWF1?tag=screenfreet0f-20
A6: 5 | B6: Wooden Kids Tool Set with Drill (44 pc) | C6: $27.99 | D6: 4.7 | E6: 512 | F6: 2K+ | G6: Nov-Feb (holiday & winter) | H6: gift ideas for 3 year boy | I6: gift ideas for 3 year olds | J6: gift ideas for 3 year girl; gift ideas for 3 year boy; educational toys for 3 year | K6: Screen-Free Gifts for Kids by Age | L6: B0F1XZ7BHY | M6: https://www.amazon.com/dp/B0F1XZ7BHY?tag=screenfreet0f-20
A7: 6 | B7: Wooden Dinosaur Stacking Toy | C7: $11.99 | D7: 4.6 | E7: 2K | F7: 4K+ | G7: Nov-Feb (holiday & winter) | H7: educational toys for 3 year | I7: gift ideas for 3 year olds | J7: gift ideas for 3 year girl; gift ideas for 3 year boy; educational toys for 3 year | K7: Screen-Free Gifts for Kids by Age | L7: B09T2CWRQ8 | M7: https://www.amazon.com/dp/B09T2CWRQ8?tag=screenfreet0f-20
A8: 7 | B8: Doctor Jupiter My First Science Experiments Kit | C8: $29.99 | D8: 4.6 | E8: 3.7K | F8: 5K+ | G8: Nov-Feb (holiday & winter) | H8: gift ideas for 5 year olds | I8: gift ideas for 5 year olds | J8: gift ideas for 5 year girl; gift ideas for 5 year boy; gift ideas for 7 year olds | K8: Screen-Free Gifts for Kids by Age | L8: B09XGMHGJ3 | M8: https://www.amazon.com/dp/B09XGMHGJ3?tag=screenfreet0f-20
A9: 8 | B9: Crayola Ultimate Light Board | C9: $19.19 | D9: 4.5 | E9: 20.2K | F9: 3K+ | G9: Nov-Feb (holiday & winter) | H9: gift ideas for 5 year girl | I9: gift ideas for 5 year olds | J9: gift ideas for 5 year girl; gift ideas for 5 year boy; gift ideas for 7 year olds | K9: Screen-Free Gifts for Kids by Age | L9: B07BF2XW1H | M9: https://www.amazon.com/dp/B07BF2XW1H?tag=screenfreet0f-20
A10: 9 | B10: LED Foam Glider Airplane Launcher (3 pack) | C10: $25.99 | D10: 4.3 | E10: 7.9K | F10: 10K+ | G10: Nov-Feb (holiday & winter) | H10: gift ideas for 5 year boy | I10: gift ideas for 5 year olds | J10: gift ideas for 5 year girl; gift ideas for 5 year boy; gift ideas for 7 year olds | K10: Screen-Free Gifts for Kids by Age | L10: B09TDP1HCV | M10: https://www.amazon.com/dp/B09TDP1HCV?tag=screenfreet0f-20
A11: 10 | B11: Play-Doh 10-Pack (2 oz cans) | C11: $7.99 | D11: 4.7 | E11: 69.6K | F11: 10K+ | G11: Nov-Feb (holiday & winter) | H11: stocking stuffers for kids 3-5 | I11: stocking stuffers for kids 3-5 | J11: stocking stuffers for kids not toys; stocking stuffers for kids ideas; stocking stuffers for kids 3-5 year | K11: Screen-Free Gifts for Kids by Age | L11: B00JM5GW10 | M11: https://www.amazon.com/dp/B00JM5GW10?tag=screenfreet0f-20
A12: 11 | B12: EooCoo Kids LCD Writing Tablet | C12: $7.99 | D12: 4.5 | E12: 2.5K | F12: 10K+ | G12: Nov-Feb (holiday & winter) | H12: stocking stuffers for kids not toys | I12: stocking stuffers for kids 3-5 | J12: stocking stuffers for kids not toys; stocking stuffers for kids ideas; stocking stuffers for kids 3-5 year | K12: Screen-Free Gifts for Kids by Age | L12: B0CCTF94DR | M12: https://www.amazon.com/dp/B0CCTF94DR?tag=screenfreet0f-20
A13: 12 | B13: GeoSafari Kidnoculars | C13: $11.44 | D13: 4.6 | E13: 24.4K | F13: 8K+ | G13: Nov-Feb (holiday & winter) | H13: stocking stuffers for kids ideas | I13: stocking stuffers for kids 3-5 | J13: stocking stuffers for kids not toys; stocking stuffers for kids ideas; stocking stuffers for kids 3-5 year | K13: Screen-Free Gifts for Kids by Age | L13: B00B1Z6EPS | M13: https://www.amazon.com/dp/B00B1Z6EPS?tag=screenfreet0f-20
... A151: 150 | B151: Melissa & Doug Primary Lacing Beads (33 pc) | C151: $19.99 | D151: 4.8 | E151: 21K | F151: 2K+ | G151: Year-round | H151: montessori toys for 2 year olds | I151: montessori toys 2-3 | J151: fine motor activities for toddlers; quiet activities for toddlers; busy toys for toddlers | K151: Montessori Toys & Life Skills for Kids | L151: B00272N8L2 | M151: https://www.amazon.com/dp/B00272N8L2?tag=screenfreet0f-20

Sheet Amazon - Sideline Ready
A1: # | B1: Product | C1: Price (Oct 30) | D1: Stars | E1: Ratings | F1: Bought last month | G1: Season | H1: Pin search phrase | I1: More parent search phrases | J1: Pinterest board | K1: Status | L1: ASIN | M1: Affiliate link
A2: 1 | B2: Stadium Seat with Back Support (2.8" Thick) | C2: $33.66 | D2: 4.7 | E2: 8.5K | F2: 5K+ | G2: Nov-Feb (holiday & winter) | H2: stadium seats for bleachers | I2: football mom must haves; sports mom must haves | J2: Stadium Seats & Bleacher Comfort | K2: Nov 2026 pins | L2: B09GS5LVTJ | M2: https://www.amazon.com/dp/B09GS5LVTJ?tag=screenfreet0f-20
A3: 2 | B3: Wide Padded Stadium Seat with Back | C3: $34.95 | D3: 4.6 | E3: 5K | F3: 3K+ | G3: Nov-Feb (holiday & winter) | H3: stadium seats | I3: high school football game essentials; sports mom gift ideas | J3: Stadium Seats & Bleacher Comfort | K3: Nov 2026 pins | L3: B0BX9NG3XR | M3: https://www.amazon.com/dp/B0BX9NG3XR?tag=screenfreet0f-20
A4: 3 | B4: 2-Pack Folding Stadium Seats | C4: $89.99 | D4: 4.3 | E4: 1.2K | F4: 2K+ | G4: Nov-Feb (holiday & winter) | H4: stadium seats for bleachers | I4: sports dad gifts; christmas gift ideas for sports mom | J4: Stadium Seats & Bleacher Comfort | K4: Nov 2026 pins | L4: B0CL4W4PXZ | M4: https://www.amazon.com/dp/B0CL4W4PXZ?tag=screenfreet0f-20
A5: 4 | B5: Reversible Stadium Seat Cushion | C5: $26.99 | D5: 4.3 | E5: 907 | F5: 1K+ | G5: Nov-Feb (holiday & winter) | H5: stadium seat cushion | I5: volleyball mom essentials; basketball mom bag essentials | J5: Stadium Seats & Bleacher Comfort | K5: Nov 2026 pins | L5: B0DJVWD5M3 | M5: https://www.amazon.com/dp/B0DJVWD5M3?tag=screenfreet0f-20
A6: 5 | B6: Oversized Wearable Blanket Sweatshirt | C6: $29.99 | D6: 4.8 | E6: 29.3K | F6: 3K+ | G6: Nov-Feb (holiday & winter) | H6: wearable stadium blanket | I6: cold football game essentials; christmas gift ideas for sports mom | J6: Cold Football Game Essentials | K6: Nov 2026 pins | L6: B07Z5LGZJM | M6: https://www.amazon.com/dp/B07Z5LGZJM?tag=screenfreet0f-20
A7: 6 | B7: Sherpa Wearable Blanket Hoodie | C7: $26.99 | D7: 4.8 | E7: 6.4K | F7: 3K+ | G7: Nov-Feb (holiday & winter) | H7: wearable stadium blanket | I7: winter football game essentials; hockey mom essentials | J7: Cold Football Game Essentials | K7: Nov 2026 pins | L7: B0BX92ZT75 | M7: https://www.amazon.com/dp/B0BX92ZT75?tag=screenfreet0f-20
A8: 7 | B8: Cordless USB Heated Shawl Blanket | C8: $65.99 | D8: 4.4 | E8: 617 | F8: 1K+ | G8: Nov-Feb (holiday & winter) | H8: heated stadium blanket | I8: cold football game essentials; sports mom gifts | J8: Cold Football Game Essentials | K8: Nov 2026 pins | L8: B0H7BYGJ45 | M8: https://www.amazon.com/dp/B0H7BYGJ45?tag=screenfreet0f-20
A9: 8 | B9: Arcturus Military Wool Blanket | C9: $42.99 | D9: 4.6 | E9: 15.5K | F9: 1K+ | G9: Nov-Feb (holiday & winter) | H9: stadium blankets | I9: stadium blankets football; sports dad essentials | J9: Cold Football Game Essentials | K9: Nov 2026 pins | L9: B01M0GLPSB | M9: https://www.amazon.com/dp/B01M0GLPSB?tag=screenfreet0f-20
A10: 9 | B10: Waterproof Outdoor Blanket (80x80) | C10: $23.99 | D10: 4.6 | E10: 844 | F10: 1K+ | G10: Year-round | H10: stadium blankets | I10: soccer mom must haves; sports wagon accessories | J10: Cold Football Game Essentials | K10: Nov 2026 pins | L10: B0F4DBP354 | M10: https://www.amazon.com/dp/B0F4DBP354?tag=screenfreet0f-20
A11: 10 | B11: HotHands Hand Warmers (40 pairs) | C11: $26.99 | D11: 4.8 | E11: 52.7K | F11: 50K+ | G11: Nov-Feb (holiday & winter) | H11: cold football game essentials | I11: winter football game essentials; hockey mom essentials | J11: Cold Football Game Essentials | K11: Nov 2026 pins | L11: B0007ZF4OA | M11: https://www.amazon.com/dp/B0007ZF4OA?tag=screenfreet0f-20
A12: 11 | B12: HotHands Hand Warmers (10 pairs) | C12: $7.48 | D12: 4.8 | E12: 20.4K | F12: 40K+ | G12: Nov-Feb (holiday & winter) | H12: football game day bag essentials | I12: sports mom bag essentials; game day bag essentials | J12: Game Day Bags & Stadium Bags | K12: Nov 2026 pins | L12: B00D7H9LIA | M12: https://www.amazon.com/dp/B00D7H9LIA?tag=screenfreet0f-20
A13: 12 | B13: Rechargeable Hand Warmers (2 pack) | C13: $17.99 | D13: 4.6 | E13: 9.4K | F13: 10K+ | G13: Nov-Feb (holiday & winter) | H13: sports mom gifts | I13: christmas gift ideas for sports mom; football mom must haves | J13: Sports Mom Gifts & Gift Baskets | K13: Nov 2026 pins | L13: B0CG65PYBV | M13: https://www.amazon.com/dp/B0CG65PYBV?tag=screenfreet0f-20
... A151: 150 | B151: Occer 12x25 Compact Binoculars | C151: $35.99 | D151: 4.4 | E151: 33.9K | F151: 10K+ | G151: Nov-Feb (holiday & winter) | H151: football game essentials | I151: stadium bag essentials; sports dad gifts | J151: Game Day Bags & Stadium Bags | K151: New - from Dec 2026 | L151: B0756BXDTX | M151: https://www.amazon.com/dp/B0756BXDTX?tag=screenfreet0f-20

Sheet Summary
A1: TPT - products by rotation
A2: Group | B2: Products
A3: A | B3: =COUNTIF('TPT - School Templates'!$F:$F,A3) -> 70
A4: B | B4: =COUNTIF('TPT - School Templates'!$F:$F,A4) -> 70
A5: A + B (every month) | B5: =COUNTIF('TPT - School Templates'!$F:$F,A5) -> 80
A6: Total | B6: =SUM(B3:B5) -> 220
A8: TPT - products by board
A9: Group | B9: Products
A10: School Psychologist Templates & Report Tools | B10: =COUNTIF('TPT - School Templates'!$E:$E,A10) -> 112
A11: IEP Templates, IEP Goal Banks & Present Levels | B11: =COUNTIF('TPT - School Templates'!$E:$E,A11) -> 9
A12: Special Education Data Sheets & Trackers | B12: =COUNTIF('TPT - School Templates'!$E:$E,A12) -> 4
A13: Behavior Intervention: FBA, BIP & Behavior Data | B13: =COUNTIF('TPT - School Templates'!$E:$E,A13) -> 12
A14: MTSS & RTI Reading Intervention Forms | B14: =COUNTIF('TPT - School Templates'!$E:$E,A14) -> 10
A15: State Reading Plans: IRP, SRIP & Reading Kits | B15: =COUNTIF('TPT - School Templates'!$E:$E,A15) -> 24
A16: Reading Assessment & Progress Monitoring | B16: =COUNTIF('TPT - School Templates'!$E:$E,A16) -> 18
A17: Report Card Comments & Parent Conferences | B17: =COUNTIF('TPT - School Templates'!$E:$E,A17) -> 15
A18: Speech Therapy Data Sheets & SLP Organization | B18: =COUNTIF('TPT - School Templates'!$E:$E,A18) -> 4
A19: School Counselor Forms & Counseling Data | B19: =COUNTIF('TPT - School Templates'!$E:$E,A19) -> 4
A20: Paraprofessional Binder & Sped Classroom Tools | B20: =COUNTIF('TPT - School Templates'!$E:$E,A20) -> 4
A21: Teacher Organization: Sub Plans & Parent Logs | B21: =COUNTIF('TPT - School Templates'!$E:$E,A21) -> 4
A22: Total | B22: =SUM(B10:B21) -> 220
A24: Dr Q Kids - products by season
A25: Group | B25: Products
A26: Nov-Feb (holiday & winter) | B26: =COUNTIF('Amazon - Dr Q Kids'!$G:$G,A26) -> 64
A27: Year-round | B27: =COUNTIF('Amazon - Dr Q Kids'!$G:$G,A27) -> 59
A28: Mar-Aug (spring & summer) | B28: =COUNTIF('Amazon - Dr Q Kids'!$G:$G,A28) -> 27
A29: Total | B29: =SUM(B26:B28) -> 150
A31: Dr Q Kids - products by board
A32: Group | B32: Products
A33: Calm Down Corner & Calming Toys for Kids | B33: =COUNTIF('Amazon - Dr Q Kids'!$K:$K,A33) -> 18
A34: Indoor Play Gym & Playroom Ideas | B34: =COUNTIF('Amazon - Dr Q Kids'!$K:$K,A34) -> 12
A35: Kids Routine Charts & Chore Charts | B35: =COUNTIF('Amazon - Dr Q Kids'!$K:$K,A35) -> 15
A36: Montessori Toys & Life Skills for Kids | B36: =COUNTIF('Amazon - Dr Q Kids'!$K:$K,A36) -> 16
A37: Outdoor Toys & Nature Kits for Kids | B37: =COUNTIF('Amazon - Dr Q Kids'!$K:$K,A37) -> 8
A38: Road Trip & Camping Essentials for Kids | B38: =COUNTIF('Amazon - Dr Q Kids'!$K:$K,A38) -> 10
A39: Screen-Free Activities & Toys for Kids | B39: =COUNTIF('Amazon - Dr Q Kids'!$K:$K,A39) -> 26
A40: Screen-Free Gifts for Kids by Age | B40: =COUNTIF('Amazon - Dr Q Kids'!$K:$K,A40) -> 19
A41: Sensory Bin Ideas & Sensory Toys | B41: =COUNTIF('Amazon - Dr Q Kids'!$K:$K,A41) -> 16
A42: Visual Timers & Visual Schedules for Kids | B42: =COUNTIF('Amazon - Dr Q Kids'!$K:$K,A42) -> 10
A43: Total | B43: =SUM(B33:B42) -> 150
...
