Workbook

Sheet Start Here
A1: Sideline Ready - Big-Ticket Amazon Products
A2: 959 products found on Amazon on Oct 30, 2026 from 154 sports-mom searches (2 pages each, Amazon's $100+ price filter).
A4: Rules every product passed
A5: Price $100 or more | 4.0 stars or higher | 100+ customer reviews | not a sponsored ad
A6: Off-topic results were removed (home space heaters, men's work boots, bed blankets, etc.), and for very crowded searches
A7: (weighted vests, dumbbells, massage guns, air tracks) only the top 10-12 by sales and reviews were kept.
A9: Tabs
A10: All Products: every product, sorted by category, then sport, then sales.
A11: Best Bets: the 302 products that also show 100+ bought last month AND 4.5+ stars. Start your bundles here.
A12: Summary: live counts by category, sport and price tier.
A14: Good to know
A15: 'Bought last month' is Amazon's own badge. A dash means Amazon didn't show one (usually under 50 sales that month).
... A18: Links use your tracking ID screenfreet0f-20.

Sheet All Products
A1: # | B1: Product | C1: Price (Oct 30) | D1: Stars | E1: Reviews | F1: Bought last month | G1: Price tier | H1: Category | I1: Sport | J1: Pinterest board | K1: Found by searching | L1: Already in 365 plan | M1: ASIN | N1: Affiliate link
A2: 1 | B2: Ninja Professional Plus Blender | C2: 109.99 | D2: 4.7 | E2: 19700 | F2: 10K+ | G2: $100-249 | H2: Athlete meals (blenders) | I2: All sports | J2: Teen Athlete Meals, Snacks & Meal Prep | K2: blender | M2: B0855B5Z6F | N2: https://www.amazon.com/dp/B0855B5Z6F?tag=screenfreet0f-20
A3: 2 | B3: nutribullet Pro+ Personal Blender | C3: 112.5 | D3: 4.5 | E3: 11900 | F3: 10K+ | G3: $100-249 | H3: Athlete meals (blenders) | I3: All sports | J3: Teen Athlete Meals, Snacks & Meal Prep | K3: blender | M3: B0BS76NRG3 | N3: https://www.amazon.com/dp/B0BS76NRG3?tag=screenfreet0f-20
A4: 3 | B4: Ninja Professional Blender 2.0 | C4: 109.99 | D4: 4.7 | E4: 48300 | F4: 8K+ | G4: $100-249 | H4: Athlete meals (blenders) | I4: All sports | J4: Teen Athlete Meals, Snacks & Meal Prep | K4: blender | M4: B0CKTYP1JT | N4: https://www.amazon.com/dp/B0CKTYP1JT?tag=screenfreet0f-20
A5: 4 | B5: Vitamix Propel Series 750 Blender | C5: 489 | D5: 4.4 | E5: 926 | F5: 2K+ | G5: $250-499 | H5: Athlete meals (blenders) | I5: All sports | J5: Teen Athlete Meals, Snacks & Meal Prep | K5: blender | M5: B0BWSJVTCJ | N5: https://www.amazon.com/dp/B0BWSJVTCJ?tag=screenfreet0f-20
A6: 5 | B6: Ninja Foodi TWISTi Blender DUO | C6: 119.94 | D6: 4.5 | E6: 4600 | F6: 1K+ | G6: $100-249 | H6: Athlete meals (blenders) | I6: All sports | J6: Teen Athlete Meals, Snacks & Meal Prep | K6: blender | M6: B09SBRGSFH | N6: https://www.amazon.com/dp/B09SBRGSFH?tag=screenfreet0f-20
A7: 6 | B7: CAP Rubber Coated Dumbbell Set with Rack | C7: 189.99 | D7: 4.4 | E7: 11800 | F7: 5K+ | G7: $100-249 | H7: Backyard & home training | I7: All sports | J7: Backyard Sports Training Equipment | K7: adjustable dumbbells | M7: B09NLF2J4P | N7: https://www.amazon.com/dp/B09NLF2J4P?tag=screenfreet0f-20
A8: 7 | B8: BowFlex SelectTech 840 Adjustable Kettlebell | C8: 149 | D8: 4.8 | E8: 7700 | F8: 3K+ | G8: $100-249 | H8: Backyard & home training | I8: All sports | J8: Backyard Sports Training Equipment | K8: adjustable dumbbells | M8: B07X64MXBS | N8: https://www.amazon.com/dp/B07X64MXBS?tag=screenfreet0f-20
A9: 8 | B9: BowFlex SelectTech Adjustable Dumbbells | C9: 399.99 | D9: 4.8 | E9: 334 | F9: 3K+ | G9: $250-499 | H9: Backyard & home training | I9: All sports | J9: Backyard Sports Training Equipment | K9: adjustable dumbbells | L9: Yes | M9: B0FRNG2N5H | N9: https://www.amazon.com/dp/B0FRNG2N5H?tag=screenfreet0f-20
A10: 9 | B10: PowerBlock Elite EXP 90 Adjustable Dumbbells | C10: 399 | D10: 4.6 | E10: 2600 | F10: 1K+ | G10: $250-499 | H10: Backyard & home training | I10: All sports | J10: Backyard Sports Training Equipment | K10: adjustable dumbbells | M10: B00A21NRNO | N10: https://www.amazon.com/dp/B00A21NRNO?tag=screenfreet0f-20
A11: 10 | B11: NordicTrack 55 lb Select-a-Weight Dumbbells | C11: 399 | D11: 4.5 | E11: 1900 | F11: 1K+ | G11: $250-499 | H11: Backyard & home training | I11: All sports | J11: Backyard Sports Training Equipment | K11: adjustable dumbbells | M11: B08BDD6GPC | N11: https://www.amazon.com/dp/B08BDD6GPC?tag=screenfreet0f-20
A12: 11 | B12: FDB2 Adjustable Dumbbell Set of 2 | C12: 139.99 | D12: 4.8 | E12: 635 | F12: 1K+ | G12: $100-249 | H12: Backyard & home training | I12: All sports | J12: Backyard Sports Training Equipment | K12: adjustable dumbbells | L12: Yes | M12: B0DK3H169C | N12: https://www.amazon.com/dp/B0DK3H169C?tag=screenfreet0f-20
A13: 12 | B13: Adjustable Dumbbell Set Pair 25/50 lb | C13: 239.99 | D13: 4.5 | E13: 164 | F13: 1K+ | G13: $100-249 | H13: Backyard & home training | I13: All sports | J13: Backyard Sports Training Equipment | K13: adjustable dumbbells | M13: B0GJ4HT8SS | N13: https://www.amazon.com/dp/B0GJ4HT8SS?tag=screenfreet0f-20
A14: 13 | B14: Lifepro Adjustable Dumbbells | C14: 189.99 | D14: 4.6 | E14: 3300 | F14: 900+ | G14: $100-249 | H14: Backyard & home training | I14: All sports | J14: Backyard Sports Training Equipment | K14: adjustable dumbbells | M14: B08QTGV9BW | N14: https://www.amazon.com/dp/B08QTGV9BW?tag=screenfreet0f-20
A15: 14 | B15: ERIC FLAG 40 lb Adjustable Weighted Vest | C15: 159.99 | D15: 4.7 | E15: 1100 | F15: 800+ | G15: $100-249 | H15: Backyard & home training | I15: All sports | J15: Backyard Sports Training Equipment | K15: weighted vest | M15: B09WB1BF81 | N15: https://www.amazon.com/dp/B09WB1BF81?tag=screenfreet0f-20
A16: 15 | B16: Adjustable Running Weighted Vest | C16: 119.99 | D16: 4.4 | E16: 489 | F16: 800+ | G16: $100-249 | H16: Backyard & home training | I16: All sports | J16: Backyard Sports Training Equipment | K16: weighted vest | M16: B0CZPRXQ3F | N16: https://www.amazon.com/dp/B0CZPRXQ3F?tag=screenfreet0f-20
A17: 16 | B17: Core Fitness Adjustable Dumbbell Set | C17: 369.99 | D17: 4.5 | E17: 1600 | F17: 700+ | G17: $250-499 | H17: Backyard & home training | I17: All sports | J17: Backyard Sports Training Equipment | K17: adjustable dumbbells | M17: B01J8S38LW | N17: https://www.amazon.com/dp/B01J8S38LW?tag=screenfreet0f-20
A18: 17 | B18: Adjustable Dumbbell Set 25/50 lb 10-in-1 | C18: 148.19 | D18: 4.5 | E18: 171 | F18: 700+ | G18: $100-249 | H18: Backyard & home training | I18: All sports | J18: Backyard Sports Training Equipment | K18: adjustable dumbbells | M18: B0FYNZQVB9 | N18: https://www.amazon.com/dp/B0FYNZQVB9?tag=screenfreet0f-20
A19: 18 | B19: CAP Power Rack Stand with Pull-Up Bar | C19: 119.99 | D19: 4.5 | E19: 4500 | F19: 600+ | G19: $100-249 | H19: Backyard & home training | I19: All sports | J19: Backyard Sports Training Equipment | K19: squat rack | M19: B00HYQP72O | N19: https://www.amazon.com/dp/B00HYQP72O?tag=screenfreet0f-20
A20: 19 | B20: Adjustable Dumbbell Set 20-90 lb | C20: 159.99 | D20: 4.3 | E20: 1400 | F20: 500+ | G20: $100-249 | H20: Backyard & home training | I20: All sports | J20: Backyard Sports Training Equipment | K20: adjustable dumbbells | M20: B0H4QWF2NK | N20: https://www.amazon.com/dp/B0H4QWF2NK?tag=screenfreet0f-20
A21: 20 | B21: Adjustable Dumbbell Set 20-90 lb 5-in-1 | C21: 159.99 | D21: 4.4 | E21: 2200 | F21: 400+ | G21: $100-249 | H21: Backyard & home training | I21: All sports | J21: Backyard Sports Training Equipment | K21: adjustable dumbbells | M21: B0HFVTQ8W8 | N21: https://www.amazon.com/dp/B0HFVTQ8W8?tag=screenfreet0f-20
A22: 21 | B22: Wolf Tactical Adjustable Weighted Vest | C22: 125.99 | D22: 4.6 | E22: 1600 | F22: 400+ | G22: $100-249 | H22: Backyard & home training | I22: All sports | J22: Backyard Sports Training Equipment | K22: weighted vest | M22: B08BX6SDJF | N22: https://www.amazon.com/dp/B08BX6SDJF?tag=screenfreet0f-20
A23: 22 | B23: Multi-Function Power Cage with J-Hooks | C23: 299.98 | D23: 4.6 | E23: 1100 | F23: 400+ | G23: $250-499 | H23: Backyard & home training | I23: All sports | J23: Backyard Sports Training Equipment | K23: squat rack | M23: B0BFQVVFB7 | N23: https://www.amazon.com/dp/B0BFQVVFB7?tag=screenfreet0f-20
A24: 23 | B24: SPORTSROYALS Power Rack | C24: 309.99 | D24: 4.5 | E24: 720 | F24: 300+ | G24: $250-499 | H24: Backyard & home training | I24: All sports | J24: Backyard Sports Training Equipment | K24: squat rack | M24: B0CXDZX29M | N24: https://www.amazon.com/dp/B0CXDZX29M?tag=screenfreet0f-20
... A66: 65 | B66: NWS Forza Spring-Loaded Agility Poles | C66: 112.99 | D66: 4.6 | E66: 126 | F66: - | G66: $100-249 | H66: Backyard & home training | I66: All sports | J66: Backyard Sports Training Equipment | K66: agility training | M66: B077PQ5MS5 | N66: https://www.amazon.com/dp/B077PQ5MS5?tag=screenfreet0f-20
A67: 66 | B67: Bushnell Velocity Radar Speed Gun | C67: 149.96 | D67: 4.3 | E67: 4600 | F67: 800+ | G67: $100-249 | H67: Backyard & home training | I67: Baseball | J67: Backyard Sports Training Equipment | K67: radar gun baseball | L67: Yes | M67: B0002X7V1Q | N67: https://www.amazon.com/dp/B0002X7V1Q?tag=screenfreet0f-20
A68: 67 | B68: Pocket Radar Smart Coach with Sports App | C68: 399 | D68: 4.6 | E68: 1400 | F68: 500+ | G68: $250-499 | H68: Backyard & home training | I68: Baseball | J68: Backyard Sports Training Equipment | K68: radar gun baseball | L68: Yes | M68: B07H7SN831 | N68: https://www.amazon.com/dp/B07H7SN831?tag=screenfreet0f-20
A69: 68 | B69: Louisville Slugger Blue Flame Pitching Machine | C69: 139 | D69: 4.5 | E69: 3600 | F69: 300+ | G69: $100-249 | H69: Backyard & home training | I69: Baseball | J69: Backyard Sports Training Equipment | K69: pitching machine | L69: Yes | M69: B000VZ2Q5G | N69: https://www.amazon.com/dp/B000VZ2Q5G?tag=screenfreet0f-20
A70: 69 | B70: Tanner Heavy Batting Tee | C70: 129.99 | D70: 4.9 | E70: 1100 | F70: 300+ | G70: $100-249 | H70: Backyard & home training | I70: Baseball | J70: Backyard Sports Training Equipment | K70: batting tee | L70: Yes | M70: B01D8ZLL2O | N70: https://www.amazon.com/dp/B01D8ZLL2O?tag=screenfreet0f-20
A71: 70 | B71: Pocket Radar Ball Coach | C71: 299 | D71: 4.6 | E71: 931 | F71: 200+ | G71: $250-499 | H71: Backyard & home training | I71: Baseball | J71: Backyard Sports Training Equipment | K71: radar gun baseball | M71: B00ISCXPJA | N71: https://www.amazon.com/dp/B00ISCXPJA?tag=screenfreet0f-20
A72: 71 | B72: Louisville Slugger Black Flame Pitching Machine | C72: 215.79 | D72: 4.5 | E72: 1400 | F72: 100+ | G72: $100-249 | H72: Backyard & home training | I72: Baseball | J72: Backyard Sports Training Equipment | K72: pitching machine | L72: Yes | M72: B00GOEZRQS | N72: https://www.amazon.com/dp/B00GOEZRQS?tag=screenfreet0f-20
A73: 72 | B73: Rope Bat Original Swing Trainer w/ 12 Balls | C73: 138.95 | D73: 4.6 | E73: 1200 | F73: 100+ | G73: $100-249 | H73: Backyard & home training | I73: Baseball | J73: Backyard Sports Training Equipment | K73: baseball rebounder | M73: B01LXO616B | N73: https://www.amazon.com/dp/B01LXO616B?tag=screenfreet0f-20
A74: 73 | B74: Heater Sports Slider Lite 360 Baseball Pitching Machine | C74: 179.99 | D74: 4.1 | E74: 529 | F74: 100+ | G74: $100-249 | H74: Backyard & home training | I74: Baseball | J74: Backyard Sports Training Equipment | K74: pitching machine | M74: B00169186O | N74: https://www.amazon.com/dp/B00169186O?tag=screenfreet0f-20
A75: 74 | B75: Athlon Rangecraft Velocity Pro Radar | C75: 399.99 | D75: 4.7 | E75: 343 | F75: 100+ | G75: $250-499 | H75: Backyard & home training | I75: Baseball | J75: Backyard Sports Training Equipment | K75: radar gun baseball | M75: B0DZQYB35H | N75: https://www.amazon.com/dp/B0DZQYB35H?tag=screenfreet0f-20
A76: 75 | B76: Lacrosse Rebounder with 5 Adjustable Angles | C76: 109.99 | D76: 4.6 | E76: 263 | F76: 100+ | G76: $100-249 | H76: Backyard & home training | I76: Baseball | J76: Backyard Sports Training Equipment | K76: baseball rebounder | M76: B0DCYRM1C7 | N76: https://www.amazon.com/dp/B0DCYRM1C7?tag=screenfreet0f-20
A77: 76 | B77: Skywalker Sports Baseball & Softball Safety Screen | C77: 109.99 | D77: 4.8 | E77: 253 | F77: 100+ | G77: $100-249 | H77: Backyard & home training | I77: Baseball | J77: Backyard Sports Training Equipment | K77: baseball hitting net | M77: B07Q34XHLL | N77: https://www.amazon.com/dp/B07Q34XHLL?tag=screenfreet0f-20
A78: 77 | B78: Portable Batting Cage 22x12x8 ft with Pitching Net | C78: 149.95 | D78: 4 | E78: 203 | F78: 100+ | G78: $100-249 | H78: Backyard & home training | I78: Baseball | J78: Backyard Sports Training Equipment | K78: pitching machine | M78: B0D6X1XTQP | N78: https://www.amazon.com/dp/B0D6X1XTQP?tag=screenfreet0f-20
A79: 78 | B79: VEVOR Multi-Sport Backstop Barricade Net | C79: 105.9 | D79: 4.4 | E79: 181 | F79: 100+ | G79: $100-249 | H79: Backyard & home training | I79: Baseball | J79: Backyard Sports Training Equipment | K79: baseball hitting net | M79: B0DDT3TCBJ | N79: https://www.amazon.com/dp/B0DDT3TCBJ?tag=screenfreet0f-20
A80: 79 | B80: Heavy-Duty Pro 9 Hole Pitching Net with Strike Zone | C80: 113.98 | D80: 4.5 | E80: 125 | F80: 100+ | G80: $100-249 | H80: Backyard & home training | I80: Baseball | J80: Backyard Sports Training Equipment | K80: pitching net | L80: Yes | M80: B0DRYKTLJ6 | N80: https://www.amazon.com/dp/B0DRYKTLJ6?tag=screenfreet0f-20
A81: 80 | B81: GoSports Hitting Mat with Batting Stance Alignment | C81: 129.99 | D81: 4.6 | E81: 122 | F81: 100+ | G81: $100-249 | H81: Backyard & home training | I81: Baseball | J81: Backyard Sports Training Equipment | K81: baseball training aid | M81: B0CVJQQXJS | N81: https://www.amazon.com/dp/B0CVJQQXJS?tag=screenfreet0f-20
...

Sheet Best Bets
A1: # | B1: Product | C1: Price (Oct 30) | D1: Stars | E1: Reviews | F1: Bought last month | G1: Price tier | H1: Category | I1: Sport | J1: Pinterest board | K1: Found by searching | L1: Already in 365 plan | M1: ASIN | N1: Affiliate link
A2: 1 | B2: Beats Solo 4 Wireless Headphones | C2: 129.95 | D2: 4.6 | E2: 30000 | F2: 10K+ | G2: $100-249 | H2: Tech gifts | I2: All sports | J2: Sports Mom Gifts & Gift Baskets | K2: noise cancelling headphones | M2: B0CZPGX972 | N2: https://www.amazon.com/dp/B0CZPGX972?tag=screenfreet0f-20
A3: 2 | B3: Apple iPad 11-inch (A16) | C3: 399 | D3: 4.7 | E3: 29900 | F3: 10K+ | G3: $250-499 | H3: Tech gifts | I3: All sports | J3: Sports Mom Gifts & Gift Baskets | K3: ipad | M3: B0DZ77D5HL | N3: https://www.amazon.com/dp/B0DZ77D5HL?tag=screenfreet0f-20
A4: 3 | B4: Beats Studio Pro Wireless Headphones | C4: 199.95 | D4: 4.5 | E4: 29000 | F4: 10K+ | G4: $100-249 | H4: Tech gifts | I4: All sports | J4: Sports Mom Gifts & Gift Baskets | K4: noise cancelling headphones | M4: B0C8PR4W22 | N4: https://www.amazon.com/dp/B0C8PR4W22?tag=screenfreet0f-20
A5: 4 | B5: Bose QuietComfort Wireless Headphones | C5: 169 | D5: 4.5 | E5: 22500 | F5: 10K+ | G5: $100-249 | H5: Tech gifts | I5: All sports | J5: Sports Mom Gifts & Gift Baskets | K5: noise cancelling headphones | M5: B0DZHR44J9 | N5: https://www.amazon.com/dp/B0DZHR44J9?tag=screenfreet0f-20
A6: 5 | B6: Ninja Professional Plus Blender | C6: 109.99 | D6: 4.7 | E6: 19700 | F6: 10K+ | G6: $100-249 | H6: Athlete meals (blenders) | I6: All sports | J6: Teen Athlete Meals, Snacks & Meal Prep | K6: blender | M6: B0855B5Z6F | N6: https://www.amazon.com/dp/B0855B5Z6F?tag=screenfreet0f-20
A7: 6 | B7: nutribullet Pro+ Personal Blender | C7: 112.5 | D7: 4.5 | E7: 11900 | F7: 10K+ | G7: $100-249 | H7: Athlete meals (blenders) | I7: All sports | J7: Teen Athlete Meals, Snacks & Meal Prep | K7: blender | M7: B0BS76NRG3 | N7: https://www.amazon.com/dp/B0BS76NRG3?tag=screenfreet0f-20
A8: 7 | B8: Apple Watch SE 3 GPS 40mm | C8: 239.99 | D8: 4.7 | E8: 4800 | F8: 10K+ | G8: $100-249 | H8: Tech gifts | I8: All sports | J8: Sports Mom Gifts & Gift Baskets | K8: apple watch | M8: B0HJ9ZNRKT | N8: https://www.amazon.com/dp/B0HJ9ZNRKT?tag=screenfreet0f-20
A9: 8 | B9: Apple AirPods Max 2 | C9: 474.99 | D9: 4.5 | E9: 1100 | F9: 10K+ | G9: $250-499 | H9: Tech gifts | I9: All sports | J9: Sports Mom Gifts & Gift Baskets | K9: airpods | M9: B0GSS4SGZR | N9: https://www.amazon.com/dp/B0GSS4SGZR?tag=screenfreet0f-20
A10: 9 | B10: Apple AirPods 5 with Noise Cancellation | C10: 149 | D10: 4.5 | E10: 438 | F10: 10K+ | G10: $100-249 | H10: Tech gifts | I10: All sports | J10: Sports Mom Gifts & Gift Baskets | K10: airpods | L10: Yes | M10: B0HJB76H2V | N10: https://www.amazon.com/dp/B0HJB76H2V?tag=screenfreet0f-20
A11: 10 | B11: Apple Watch Series 12 GPS 42mm | C11: 389.99 | D11: 4.7 | E11: 334 | F11: 10K+ | G11: $250-499 | H11: Tech gifts | I11: All sports | J11: Sports Mom Gifts & Gift Baskets | K11: apple watch | M11: B0HJ9ZXCSD | N11: https://www.amazon.com/dp/B0HJ9ZXCSD?tag=screenfreet0f-20
A12: 11 | B12: Ninja Professional Blender 2.0 | C12: 109.99 | D12: 4.7 | E12: 48300 | F12: 8K+ | G12: $100-249 | H12: Athlete meals (blenders) | I12: All sports | J12: Teen Athlete Meals, Snacks & Meal Prep | K12: blender | M12: B0CKTYP1JT | N12: https://www.amazon.com/dp/B0CKTYP1JT?tag=screenfreet0f-20
A13: 12 | B13: Jackery Explorer 300 Portable Power Station | C13: 289 | D13: 4.6 | E13: 11300 | F13: 8K+ | G13: $250-499 | H13: Tailgate & power | I13: All sports | J13: Sports Dad Essentials & Gifts | K13: power station | L13: Yes | M13: B082TMBYR6 | N13: https://www.amazon.com/dp/B082TMBYR6?tag=screenfreet0f-20
A14: 13 | B14: Garmin Forerunner 165 Running Smartwatch | C14: 192.49 | D14: 4.6 | E14: 5300 | F14: 7K+ | G14: $100-249 | H14: Tech gifts | I14: All sports | J14: Sports Mom Gifts & Gift Baskets | K14: garmin watch | L14: Yes | M14: B0CT3SGHXL | N14: https://www.amazon.com/dp/B0CT3SGHXL?tag=screenfreet0f-20
A15: 14 | B15: Theragun Relief Massage Gun | C15: 159.99 | D15: 4.5 | E15: 2600 | F15: 6K+ | G15: $100-249 | H15: Recovery | I15: All sports | J15: Sports Mom Gifts & Gift Baskets | K15: massage gun | L15: Yes | M15: B0CNS894RH | N15: https://www.amazon.com/dp/B0CNS894RH?tag=screenfreet0f-20
A16: 15 | B16: Bose SoundLink Flex Bluetooth Speaker (2nd Gen) | C16: 149 | D16: 4.7 | E16: 13600 | F16: 5K+ | G16: $100-249 | H16: Tailgate & power | I16: All sports | J16: Sports Dad Essentials & Gifts | K16: bluetooth speaker | M16: B0D6WD2QSQ | N16: https://www.amazon.com/dp/B0D6WD2QSQ?tag=screenfreet0f-20
A17: 16 | B17: Skullcandy Crusher ANC 2 Headphones | C17: 213.41 | D17: 4.6 | E17: 4800 | F17: 5K+ | G17: $100-249 | H17: Tech gifts | I17: All sports | J17: Sports Mom Gifts & Gift Baskets | K17: noise cancelling headphones | M17: B0C9L8ZR6Q | N17: https://www.amazon.com/dp/B0C9L8ZR6Q?tag=screenfreet0f-20
A18: 17 | B18: Callaway 300 Pro Golf Laser Rangefinder | C18: 194.95 | D18: 4.6 | E18: 12200 | F18: 4K+ | G18: $100-249 | H18: Golf (sports dad gifts) | I18: Golf | J18: Sports Dad Essentials & Gifts | K18: golf launch monitor | M18: B01KP195PY | N18: https://www.amazon.com/dp/B01KP195PY?tag=screenfreet0f-20
A19: 18 | B19: UGG Women's Tasman II Slipper | C19: 129.95 | D19: 4.7 | E19: 3900 | F19: 4K+ | G19: $100-249 | H19: Cold-weather gear | I19: All sports | J19: Cold Football Game Essentials | K19: ugg boots | M19: B0DPJH8ZRQ | N19: https://www.amazon.com/dp/B0DPJH8ZRQ?tag=screenfreet0f-20
A20: 19 | B20: DJI Osmo Action 4 Essential Combo | C20: 229 | D20: 4.7 | E20: 2500 | F20: 4K+ | G20: $100-249 | H20: Filming the game | I20: All sports | J20: Sports Mom Gifts & Gift Baskets | K20: action camera | M20: B0DS2B3P2B | N20: https://www.amazon.com/dp/B0DS2B3P2B?tag=screenfreet0f-20
A21: 20 | B21: EUHOMY Nugget Ice Maker with Carry Handle | C21: 147.16 | D21: 4.6 | E21: 1700 | F21: 4K+ | G21: $100-249 | H21: Coolers & drinks | I21: All sports | J21: Travel Ball & Tournament Must Haves | K21: portable ice maker | M21: B0GXB42S3F | N21: https://www.amazon.com/dp/B0GXB42S3F?tag=screenfreet0f-20
A22: 21 | B22: BLUETTI Elite 30 V2 Portable Power Station | C22: 279.99 | D22: 4.5 | E22: 1200 | F22: 4K+ | G22: $250-499 | H22: Tailgate & power | I22: All sports | J22: Sports Dad Essentials & Gifts | K22: power station | M22: B0F42HLLSC | N22: https://www.amazon.com/dp/B0F42HLLSC?tag=screenfreet0f-20
A23: 22 | B23: BowFlex SelectTech 840 Adjustable Kettlebell | C23: 149 | D23: 4.8 | E23: 7700 | F23: 3K+ | G23: $100-249 | H23: Backyard & home training | I23: All sports | J23: Backyard Sports Training Equipment | K23: adjustable dumbbells | M23: B07X64MXBS | N23: https://www.amazon.com/dp/B07X64MXBS?tag=screenfreet0f-20
A24: 23 | B24: Jackery Explorer 1000 v2 Power Station | C24: 559 | D24: 4.7 | E24: 3700 | F24: 3K+ | G24: $500-999 | H24: Tailgate & power | I24: All sports | J24: Sports Dad Essentials & Gifts | K24: power station | L24: Yes | M24: B0D7PPG25F | N24: https://www.amazon.com/dp/B0D7PPG25F?tag=screenfreet0f-20
A25: 24 | B25: Apple iPad mini (A17 Pro) | C25: 559.99 | D25: 4.7 | E25: 3400 | F25: 3K+ | G25: $500-999 | H25: Tech gifts | I25: All sports | J25: Sports Mom Gifts & Gift Baskets | K25: ipad | M25: B0DK3W6TV6 | N25: https://www.amazon.com/dp/B0DK3W6TV6?tag=screenfreet0f-20
A26: 25 | B26: Apple Watch SE 3 GPS + Cellular 40mm | C26: 299 | D26: 4.6 | E26: 625 | F26: 3K+ | G26: $250-499 | H26: Tech gifts | I26: All sports | J26: Sports Mom Gifts & Gift Baskets | K26: apple watch | M26: B0HJB73N19 | N26: https://www.amazon.com/dp/B0HJB73N19?tag=screenfreet0f-20
A27: 26 | B27: BowFlex SelectTech Adjustable Dumbbells | C27: 399.99 | D27: 4.8 | E27: 334 | F27: 3K+ | G27: $250-499 | H27: Backyard & home training | I27: All sports | J27: Backyard Sports Training Equipment | K27: adjustable dumbbells | L27: Yes | M27: B0FRNG2N5H | N27: https://www.amazon.com/dp/B0FRNG2N5H?tag=screenfreet0f-20
A28: 27 | B28: The North Face Borealis Backpack | C28: 115 | D28: 4.7 | E28: 16500 | F28: 2K+ | G28: $100-249 | H28: Bags | I28: All sports | J28: Game Day Bags & Stadium Bags | K28: backpack sports | M28: B0CN9SD8JF | N28: https://www.amazon.com/dp/B0CN9SD8JF?tag=screenfreet0f-20
A29: 28 | B29: CROWN SHADES 10x10 Pop Up Canopy | C29: 139.99 | D29: 4.6 | E29: 11500 | F29: 2K+ | G29: $100-249 | H29: Canopies & shade | I29: All sports | J29: Travel Ball & Tournament Must Haves | K29: canopy with sidewalls | L29: Yes | M29: B078XR1CS8 | N29: https://www.amazon.com/dp/B078XR1CS8?tag=screenfreet0f-20
A30: 29 | B30: Theragun Prime 6th Gen Massage Gun | C30: 329.99 | D30: 4.6 | E30: 6800 | F30: 2K+ | G30: $250-499 | H30: Recovery | I30: All sports | J30: Sports Mom Gifts & Gift Baskets | K30: massage gun | M30: B0FKCJNHWB | N30: https://www.amazon.com/dp/B0FKCJNHWB?tag=screenfreet0f-20
A31: 30 | B31: DJI Osmo Action 4 Standard Combo | C31: 239 | D31: 4.6 | E31: 5200 | F31: 2K+ | G31: $100-249 | H31: Filming the game | I31: All sports | J31: Sports Mom Gifts & Gift Baskets | K31: action camera | M31: B0C783YNW7 | N31: https://www.amazon.com/dp/B0C783YNW7?tag=screenfreet0f-20
A32: 31 | B32: CROWN SHADES 10x10 Pop Up Canopy with 1 Side Wall | C32: 149.99 | D32: 4.6 | E32: 4500 | F32: 2K+ | G32: $100-249 | H32: Canopies & shade | I32: All sports | J32: Travel Ball & Tournament Must Haves | K32: canopy with sidewalls | M32: B09KLVB9X7 | N32: https://www.amazon.com/dp/B09KLVB9X7?tag=screenfreet0f-20
A33: 32 | B33: Blackstone 1883 Original 28" Griddle with Hood | C33: 399 | D33: 4.7 | E33: 2000 | F33: 2K+ | G33: $250-499 | H33: Tailgate & power | I33: All sports | J33: Sports Dad Essentials & Gifts | K33: griddle | M33: B08BWWKKKL | N33: https://www.amazon.com/dp/B08BWWKKKL?tag=screenfreet0f-20
A34: 33 | B34: Theragun Mini 3rd Gen | C34: 219.99 | D34: 4.6 | E34: 1900 | F34: 2K+ | G34: $100-249 | H34: Recovery | I34: All sports | J34: Sports Mom Gifts & Gift Baskets | K34: massage gun | L34: Yes | M34: B0DV7JN7ZD | N34: https://www.amazon.com/dp/B0DV7JN7ZD?tag=screenfreet0f-20
A35: 34 | B35: Anker SOLIX C1000 Gen 2 Power Station | C35: 499.99 | D35: 4.7 | E35: 1700 | F35: 2K+ | G35: $250-499 | H35: Tailgate & power | I35: All sports | J35: Sports Dad Essentials & Gifts | K35: power station | M35: B0FN7MSY4L | N35: https://www.amazon.com/dp/B0FN7MSY4L?tag=screenfreet0f-20
A36: 35 | B36: Vortex Triumph HD 12x50 Binoculars | C36: 119 | D36: 4.7 | E36: 266 | F36: 2K+ | G36: $100-249 | H36: Filming the game | I36: All sports | J36: Sports Mom Gifts & Gift Baskets | K36: binoculars | M36: B0GNTHY8JK | N36: https://www.amazon.com/dp/B0GNTHY8JK?tag=screenfreet0f-20
A37: 36 | B37: Opove M3 Pro 2 Massage Gun | C37: 129.99 | D37: 4.7 | E37: 20400 | F37: 1K+ | G37: $100-249 | H37: Recovery | I37: All sports | J37: Sports Mom Gifts & Gift Baskets | K37: massage gun | M37: B07TWFK7JW | N37: https://www.amazon.com/dp/B07TWFK7JW?tag=screenfreet0f-20
A38: 37 | B38: FLEXIMOUNTS 4x8 Overhead Garage Storage Rack | C38: 145.99 | D38: 4.7 | E38: 19300 | F38: 1K+ | G38: $100-249 | H38: Car & garage storage | I38: All sports | J38: Sports Equipment Storage & Garage Organization | K38: garage storage system | L38: Yes | M38: B0194R5BSA | N38: https://www.amazon.com/dp/B0194R5BSA?tag=screenfreet0f-20
A39: 38 | B39: JBL Xtreme 2 Waterproof Bluetooth Speaker | C39: 199.99 | D39: 4.7 | E39: 15500 | F39: 1K+ | G39: $100-249 | H39: Tailgate & power | I39: All sports | J39: Sports Dad Essentials & Gifts | K39: bluetooth speaker | M39: B07CVPZJTV | N39: https://www.amazon.com/dp/B07CVPZJTV?tag=screenfreet0f-20
A40: 39 | B40: DJI Osmo Mobile 8 + Mic Mini Transmitter | C40: 182 | D40: 4.6 | E40: 14200 | F40: 1K+ | G40: $100-249 | H40: Filming the game | I40: All sports | J40: Sports Mom Gifts & Gift Baskets | K40: gimbal stabilizer | M40: B0GR9YG1LY | N40: https://www.amazon.com/dp/B0GR9YG1LY?tag=screenfreet0f-20
...

Sheet Summary
A1: Summary
A3: By category
A4: Group | B4: Products | C4: Best Bets
A5: Athlete meals (blenders) | B5: =COUNTIF('All Products'!H:H,A5) -> 5 | C5: =COUNTIF('Best Bets'!H:H,A5) -> 4
A6: Backyard & home training | B6: =COUNTIF('All Products'!H:H,A6) -> 358 | C6: =COUNTIF('Best Bets'!H:H,A6) -> 80
A7: Bags | B7: =COUNTIF('All Products'!H:H,A7) -> 55 | C7: =COUNTIF('Best Bets'!H:H,A7) -> 15
A8: Canopies & shade | B8: =COUNTIF('All Products'!H:H,A8) -> 22 | C8: =COUNTIF('Best Bets'!H:H,A8) -> 6
A9: Car & garage storage | B9: =COUNTIF('All Products'!H:H,A9) -> 32 | C9: =COUNTIF('Best Bets'!H:H,A9) -> 8
A10: Cold-weather gear | B10: =COUNTIF('All Products'!H:H,A10) -> 52 | C10: =COUNTIF('Best Bets'!H:H,A10) -> 25
A11: Coolers & drinks | B11: =COUNTIF('All Products'!H:H,A11) -> 38 | C11: =COUNTIF('Best Bets'!H:H,A11) -> 14
A12: Filming the game | B12: =COUNTIF('All Products'!H:H,A12) -> 42 | C12: =COUNTIF('Best Bets'!H:H,A12) -> 32
A13: Game room & arcade | B13: =COUNTIF('All Products'!H:H,A13) -> 5 | C13: =COUNTIF('Best Bets'!H:H,A13) -> 0
A14: Gifts for kids & teens | B14: =COUNTIF('All Products'!H:H,A14) -> 5 | C14: =COUNTIF('Best Bets'!H:H,A14) -> 0
A15: Golf (sports dad gifts) | B15: =COUNTIF('All Products'!H:H,A15) -> 27 | C15: =COUNTIF('Best Bets'!H:H,A15) -> 12
A16: Mom style | B16: =COUNTIF('All Products'!H:H,A16) -> 9 | C16: =COUNTIF('Best Bets'!H:H,A16) -> 4
... A24: Wagons | B24: =COUNTIF('All Products'!H:H,A24) -> 24 | C24: =COUNTIF('Best Bets'!H:H,A24) -> 12
A25: Total | B25: =SUM(B5:B24) -> 959 | C25: =SUM(C5:C24) -> 302
A27: By sport
A28: Group | B28: Products | C28: Best Bets
A29: All sports | B29: =COUNTIF('All Products'!I:I,A29) -> 464 | C29: =COUNTIF('Best Bets'!I:I,A29) -> 223
A30: Baseball | B30: =COUNTIF('All Products'!I:I,A30) -> 126 | C30: =COUNTIF('Best Bets'!I:I,A30) -> 14
A31: Basketball | B31: =COUNTIF('All Products'!I:I,A31) -> 83 | C31: =COUNTIF('Best Bets'!I:I,A31) -> 12
A32: Cheer | B32: =COUNTIF('All Products'!I:I,A32) -> 12 | C32: =COUNTIF('Best Bets'!I:I,A32) -> 2
A33: Dance | B33: =COUNTIF('All Products'!I:I,A33) -> 2 | C33: =COUNTIF('Best Bets'!I:I,A33) -> 0
A34: Football | B34: =COUNTIF('All Products'!I:I,A34) -> 21 | C34: =COUNTIF('Best Bets'!I:I,A34) -> 1
A35: Golf | B35: =COUNTIF('All Products'!I:I,A35) -> 33 | C35: =COUNTIF('Best Bets'!I:I,A35) -> 14
A36: Gymnastics | B36: =COUNTIF('All Products'!I:I,A36) -> 34 | C36: =COUNTIF('Best Bets'!I:I,A36) -> 13
A37: Hockey | B37: =COUNTIF('All Products'!I:I,A37) -> 31 | C37: =COUNTIF('Best Bets'!I:I,A37) -> 3
A38: Lacrosse | B38: =COUNTIF('All Products'!I:I,A38) -> 13 | C38: =COUNTIF('Best Bets'!I:I,A38) -> 0
A39: Pickleball | B39: =COUNTIF('All Products'!I:I,A39) -> 23 | C39: =COUNTIF('Best Bets'!I:I,A39) -> 6
A40: Soccer | B40: =COUNTIF('All Products'!I:I,A40) -> 48 | C40: =COUNTIF('Best Bets'!I:I,A40) -> 4
... A46: Wrestling | B46: =COUNTIF('All Products'!I:I,A46) -> 7 | C46: =COUNTIF('Best Bets'!I:I,A46) -> 0
A47: Total | B47: =SUM(B29:B46) -> 959 | C47: =SUM(C29:C46) -> 302
A49: By price tier
A50: Group | B50: Products | C50: Best Bets
A51: $100-249 | B51: =COUNTIF('All Products'!G:G,A51) -> 777 | C51: =COUNTIF('Best Bets'!G:G,A51) -> 239
A52: $250-499 | B52: =COUNTIF('All Products'!G:G,A52) -> 143 | C52: =COUNTIF('Best Bets'!G:G,A52) -> 50
A53: $500-999 | B53: =COUNTIF('All Products'!G:G,A53) -> 27 | C53: =COUNTIF('Best Bets'!G:G,A53) -> 10
A54: $1,000+ | B54: =COUNTIF('All Products'!G:G,A54) -> 12 | C54: =COUNTIF('Best Bets'!G:G,A54) -> 3
A55: Total | B55: =SUM(B51:B54) -> 959 | C55: =SUM(C51:C54) -> 302
